<?xml version="1.0"?>
<robot xmlns:xacro="http://ros.org/wiki/xacro">
  <!-- Include common macros -->
  <xacro:include filename="$(find onrobot_description)/urdf/common/rg.macro.xacro" />

  <!-- Define component macros -->
  <xacro:macro name="inner_knuckle_joint" params="prefix fingerprefix reflect">
    <joint name="${prefix}${fingerprefix}_inner_knuckle_joint" type="revolute">
      <origin xyz="0 ${reflect * -0.012720} 0.159500" rpy="0 0 ${(reflect - 1) * pi / 2}" />
      <parent link="${prefix}onrobot_base_link" />
      <child link="${prefix}${fingerprefix}_inner_knuckle" />
      <axis xyz="1 0 0" />
      <limit lower="-0.628319" upper="0.628319" velocity="2.0" effort="1000" />
      <mimic joint="${prefix}finger_joint" multiplier="-1" offset="0" />
    </joint>
  </xacro:macro>

  <xacro:macro name="inner_finger_joint" params="prefix fingerprefix">
    <joint name="${prefix}${fingerprefix}_inner_finger_joint" type="revolute">
      <origin xyz="0 ${-(0.071447-0.024112)} ${0.201308-0.136813}" rpy="0 0 0" />
      <parent link="${prefix}${fingerprefix}_outer_knuckle" />
      <child link="${prefix}${fingerprefix}_inner_finger" />
      <axis xyz="1 0 0" />
      <limit lower="-0.872665" upper="0.872665" velocity="2.0" effort="1000" />
      <mimic joint="${prefix}finger_joint" multiplier="1" offset="0" />
    </joint>

    <link name="${prefix}${fingerprefix}_finger_tip" />
    <joint name="${prefix}${fingerprefix}_finger_tip_joint" type="fixed">
      <origin xyz="0 0.025 0.052" rpy="0 0 0" />
      <parent link="${prefix}${fingerprefix}_inner_finger" />
      <child link="${prefix}${fingerprefix}_finger_tip" />
    </joint>
  </xacro:macro>

  <xacro:macro name="finger_joint" params="prefix">
    <link name="${prefix}finger_width_mock_link">
      <inertial> <!-- Gazebo requires inertia, even if this isn't a physical link-->
        <mass value="1.0E-6" />
        <inertia ixx="1.0E-6" ixy="1.0E-9" ixz="1.0E-9" iyy="1.0E-6" iyz="1.0E-9" izz="1.0E-6" />
      </inertial>
    </link>
    <joint name="${prefix}finger_width" type="prismatic">
      <origin xyz="0 0 0" rpy="0 0 0" />
      <parent link="${prefix}onrobot_base_link" />
      <child link="${prefix}finger_width_mock_link" />
      <axis xyz="0 0 1" />
      <limit lower="0" upper="0.160" velocity="0.160" effort="120" />
    </joint>

    <joint name="${prefix}finger_joint" type="revolute">
      <origin xyz="0 -0.024112 0.136813" rpy="0 0 0" />
      <parent link="${prefix}onrobot_base_link" />
      <child link="${prefix}left_outer_knuckle" />
      <axis xyz="-1 0 0" />
      <limit lower="-0.628319" upper="0.628319" velocity="2.0" effort="1000" />
      <mimic joint="${prefix}finger_width" multiplier="${0.88 * ((-0.628319 - 0.628319) / 0.160)}"
        offset="0.628319" />
    </joint>
    <xacro:finger_joints prefix="${prefix}" fingerprefix="left" reflect="1.0" />
  </xacro:macro>

  <xacro:macro name="right_outer_knuckle_joint" params="prefix">
    <joint name="${prefix}right_outer_knuckle_joint" type="revolute">
      <origin xyz="0 0.024112 0.136813" rpy="0 0 ${pi}" />
      <parent link="${prefix}onrobot_base_link" />
      <child link="${prefix}right_outer_knuckle" />
      <axis xyz="1 0 0" />
      <limit lower="-0.628319" upper="0.628319" velocity="2.0" effort="1000" />
      <mimic joint="${prefix}finger_joint" multiplier="-1" offset="0" />
    </joint>
    <xacro:finger_joints prefix="${prefix}" fingerprefix="right" reflect="-1.0" />
  </xacro:macro>

  <xacro:macro name="gripper_tcp" params="prefix">
    <link name="${prefix}gripper_tcp" />
    <joint name="${prefix}tcp_joint" type="fixed">
      <origin xyz="0 0 0.268" rpy="0 0 0" />
      <parent link="${prefix}onrobot_base_link" />
      <child link="${prefix}gripper_tcp" />
    </joint>
  </xacro:macro>

  <!-- Main description macro -->
  <xacro:macro name="rg6_description" params="prefix parent *origin">
    <xacro:onrobot_base_link onrobot_type="rg6" prefix="${prefix}" />
    <xacro:finger_links onrobot_type="rg6" prefix="${prefix}" fingerprefix="left" />
    <xacro:finger_links onrobot_type="rg6" prefix="${prefix}" fingerprefix="right" />
    <xacro:finger_joint prefix="${prefix}" />
    <xacro:gripper_tcp prefix="${prefix}" />
    <xacro:right_outer_knuckle_joint prefix="${prefix}" />
    <xacro:transmission_macro prefix="${prefix}" joint_name="finger_width" />

    <joint name="${prefix}base_joint" type="fixed">
      <xacro:insert_block name="origin" />
      <parent link="${parent}" />
      <child link="${prefix}onrobot_base_link" />
    </joint>
  </xacro:macro>
</robot>
